[2022-06-18 08:18:22,924] {taskinstance.py:1032} INFO - Dependencies all met for <TaskInstance: simple_etl_dag.run_etl_task manual__2022-06-18T08:18:19.386332+00:00 [queued]>
[2022-06-18 08:18:22,975] {taskinstance.py:1032} INFO - Dependencies all met for <TaskInstance: simple_etl_dag.run_etl_task manual__2022-06-18T08:18:19.386332+00:00 [queued]>
[2022-06-18 08:18:22,977] {taskinstance.py:1238} INFO - 
--------------------------------------------------------------------------------
[2022-06-18 08:18:22,979] {taskinstance.py:1239} INFO - Starting attempt 1 of 1
[2022-06-18 08:18:22,981] {taskinstance.py:1240} INFO - 
--------------------------------------------------------------------------------
[2022-06-18 08:18:23,032] {taskinstance.py:1259} INFO - Executing <Task(PythonOperator): run_etl_task> on 2022-06-18 08:18:19.386332+00:00
[2022-06-18 08:18:23,042] {standard_task_runner.py:52} INFO - Started process 3557 to run task
[2022-06-18 08:18:23,059] {standard_task_runner.py:76} INFO - Running: ['***', 'tasks', 'run', 'simple_etl_dag', 'run_etl_task', 'manual__2022-06-18T08:18:19.386332+00:00', '--job-id', '9', '--raw', '--subdir', 'DAGS_FOLDER/simple_etl.py', '--cfg-path', '/tmp/tmpqef3grh8', '--error-file', '/tmp/tmpu9t5r5dc']
[2022-06-18 08:18:23,063] {standard_task_runner.py:77} INFO - Job 9: Subtask run_etl_task
[2022-06-18 08:18:23,245] {logging_mixin.py:109} INFO - Running <TaskInstance: simple_etl_dag.run_etl_task manual__2022-06-18T08:18:19.386332+00:00 [running]> on host b7a0af5ee6a4
[2022-06-18 08:18:23,454] {taskinstance.py:1426} INFO - Exporting the following env vars:
AIRFLOW_CTX_DAG_OWNER=Airflow
AIRFLOW_CTX_DAG_ID=simple_etl_dag
AIRFLOW_CTX_TASK_ID=run_etl_task
AIRFLOW_CTX_EXECUTION_DATE=2022-06-18T08:18:19.386332+00:00
AIRFLOW_CTX_DAG_RUN_ID=manual__2022-06-18T08:18:19.386332+00:00
[2022-06-18 08:18:23,462] {logging_mixin.py:109} INFO - >>> Running 'etl' function. Logged at 2022-06-18 08:18:23.462430+00:00
[2022-06-18 08:18:23,465] {logging_mixin.py:109} INFO - >>> Running 'connect_db' function. Logged at 2022-06-18 08:18:23.465339+00:00
[2022-06-18 08:18:23,469] {logging_mixin.py:109} INFO - Connecting to DB
[2022-06-18 08:18:23,522] {logging_mixin.py:109} INFO - >>> Function: 'connect_db' executed. Logged at 2022-06-18 08:18:23.465339+00:00
[2022-06-18 08:18:23,527] {logging_mixin.py:109} INFO - >>> Running 'extract' function. Logged at 2022-06-18 08:18:23.527351+00:00
[2022-06-18 08:18:23,531] {logging_mixin.py:109} INFO - Reading dataset from https://archive.ics.uci.edu/ml/machine-learning-databases/wine-quality/winequality-red.csv
[2022-06-18 08:18:25,246] {logging_mixin.py:109} INFO - >>> Function: 'extract' executed. Logged at 2022-06-18 08:18:23.527351+00:00
[2022-06-18 08:18:25,249] {logging_mixin.py:109} INFO - >>> Running 'transform' function. Logged at 2022-06-18 08:18:25.248906+00:00
[2022-06-18 08:18:25,251] {logging_mixin.py:109} INFO - Transforming data
[2022-06-18 08:18:25,260] {taskinstance.py:1700} ERROR - Task failed with exception
Traceback (most recent call last):
  File "/home/airflow/.local/lib/python3.7/site-packages/pandas/core/indexes/base.py", line 3361, in get_loc
    return self._engine.get_loc(casted_key)
  File "pandas/_libs/index.pyx", line 76, in pandas._libs.index.IndexEngine.get_loc
  File "pandas/_libs/index.pyx", line 108, in pandas._libs.index.IndexEngine.get_loc
  File "pandas/_libs/hashtable_class_helper.pxi", line 5198, in pandas._libs.hashtable.PyObjectHashTable.get_item
  File "pandas/_libs/hashtable_class_helper.pxi", line 5206, in pandas._libs.hashtable.PyObjectHashTable.get_item
KeyError: 'winecolor'

The above exception was the direct cause of the following exception:

Traceback (most recent call last):
  File "/home/airflow/.local/lib/python3.7/site-packages/airflow/models/taskinstance.py", line 1329, in _run_raw_task
    self._execute_task_with_callbacks(context)
  File "/home/airflow/.local/lib/python3.7/site-packages/airflow/models/taskinstance.py", line 1455, in _execute_task_with_callbacks
    result = self._execute_task(context, self.task)
  File "/home/airflow/.local/lib/python3.7/site-packages/airflow/models/taskinstance.py", line 1511, in _execute_task
    result = execute_callable(context=context)
  File "/home/airflow/.local/lib/python3.7/site-packages/airflow/operators/python.py", line 174, in execute
    return_value = self.execute_callable()
  File "/home/airflow/.local/lib/python3.7/site-packages/airflow/operators/python.py", line 185, in execute_callable
    return self.python_callable(*self.op_args, **self.op_kwargs)
  File "/opt/airflow/dags/simple_etl.py", line 29, in inner
    to_execute = func(*args, **kwargs)
  File "/opt/airflow/dags/simple_etl.py", line 94, in etl
    clean_df = transform(raw_df)
  File "/opt/airflow/dags/simple_etl.py", line 29, in inner
    to_execute = func(*args, **kwargs)
  File "/opt/airflow/dags/simple_etl.py", line 59, in transform
    winecolor_encoded = pd.get_dummies(df_transform["winecolor"], prefix="winecolor")
  File "/home/airflow/.local/lib/python3.7/site-packages/pandas/core/frame.py", line 3458, in __getitem__
    indexer = self.columns.get_loc(key)
  File "/home/airflow/.local/lib/python3.7/site-packages/pandas/core/indexes/base.py", line 3363, in get_loc
    raise KeyError(key) from err
KeyError: 'winecolor'
[2022-06-18 08:18:25,334] {taskinstance.py:1277} INFO - Marking task as FAILED. dag_id=simple_etl_dag, task_id=run_etl_task, execution_date=20220618T081819, start_date=20220618T081822, end_date=20220618T081825
[2022-06-18 08:18:25,394] {standard_task_runner.py:92} ERROR - Failed to execute job 9 for task run_etl_task
Traceback (most recent call last):
  File "/home/airflow/.local/lib/python3.7/site-packages/pandas/core/indexes/base.py", line 3361, in get_loc
    return self._engine.get_loc(casted_key)
  File "pandas/_libs/index.pyx", line 76, in pandas._libs.index.IndexEngine.get_loc
  File "pandas/_libs/index.pyx", line 108, in pandas._libs.index.IndexEngine.get_loc
  File "pandas/_libs/hashtable_class_helper.pxi", line 5198, in pandas._libs.hashtable.PyObjectHashTable.get_item
  File "pandas/_libs/hashtable_class_helper.pxi", line 5206, in pandas._libs.hashtable.PyObjectHashTable.get_item
KeyError: 'winecolor'

The above exception was the direct cause of the following exception:

Traceback (most recent call last):
  File "/home/airflow/.local/lib/python3.7/site-packages/airflow/task/task_runner/standard_task_runner.py", line 85, in _start_by_fork
    args.func(args, dag=self.dag)
  File "/home/airflow/.local/lib/python3.7/site-packages/airflow/cli/cli_parser.py", line 48, in command
    return func(*args, **kwargs)
  File "/home/airflow/.local/lib/python3.7/site-packages/airflow/utils/cli.py", line 92, in wrapper
    return f(*args, **kwargs)
  File "/home/airflow/.local/lib/python3.7/site-packages/airflow/cli/commands/task_command.py", line 298, in task_run
    _run_task_by_selected_method(args, dag, ti)
  File "/home/airflow/.local/lib/python3.7/site-packages/airflow/cli/commands/task_command.py", line 107, in _run_task_by_selected_method
    _run_raw_task(args, ti)
  File "/home/airflow/.local/lib/python3.7/site-packages/airflow/cli/commands/task_command.py", line 184, in _run_raw_task
    error_file=args.error_file,
  File "/home/airflow/.local/lib/python3.7/site-packages/airflow/utils/session.py", line 70, in wrapper
    return func(*args, session=session, **kwargs)
  File "/home/airflow/.local/lib/python3.7/site-packages/airflow/models/taskinstance.py", line 1329, in _run_raw_task
    self._execute_task_with_callbacks(context)
  File "/home/airflow/.local/lib/python3.7/site-packages/airflow/models/taskinstance.py", line 1455, in _execute_task_with_callbacks
    result = self._execute_task(context, self.task)
  File "/home/airflow/.local/lib/python3.7/site-packages/airflow/models/taskinstance.py", line 1511, in _execute_task
    result = execute_callable(context=context)
  File "/home/airflow/.local/lib/python3.7/site-packages/airflow/operators/python.py", line 174, in execute
    return_value = self.execute_callable()
  File "/home/airflow/.local/lib/python3.7/site-packages/airflow/operators/python.py", line 185, in execute_callable
    return self.python_callable(*self.op_args, **self.op_kwargs)
  File "/opt/airflow/dags/simple_etl.py", line 29, in inner
    to_execute = func(*args, **kwargs)
  File "/opt/airflow/dags/simple_etl.py", line 94, in etl
    clean_df = transform(raw_df)
  File "/opt/airflow/dags/simple_etl.py", line 29, in inner
    to_execute = func(*args, **kwargs)
  File "/opt/airflow/dags/simple_etl.py", line 59, in transform
    winecolor_encoded = pd.get_dummies(df_transform["winecolor"], prefix="winecolor")
  File "/home/airflow/.local/lib/python3.7/site-packages/pandas/core/frame.py", line 3458, in __getitem__
    indexer = self.columns.get_loc(key)
  File "/home/airflow/.local/lib/python3.7/site-packages/pandas/core/indexes/base.py", line 3363, in get_loc
    raise KeyError(key) from err
KeyError: 'winecolor'
[2022-06-18 08:18:25,457] {local_task_job.py:154} INFO - Task exited with return code 1
[2022-06-18 08:18:25,583] {local_task_job.py:264} INFO - 0 downstream tasks scheduled from follow-on schedule check
