[2022-06-18 08:08:33,163] {taskinstance.py:1032} INFO - Dependencies all met for <TaskInstance: simple_etl_dag.run_etl_task manual__2022-06-18T08:08:29.183648+00:00 [queued]>
[2022-06-18 08:08:33,217] {taskinstance.py:1032} INFO - Dependencies all met for <TaskInstance: simple_etl_dag.run_etl_task manual__2022-06-18T08:08:29.183648+00:00 [queued]>
[2022-06-18 08:08:33,219] {taskinstance.py:1238} INFO - 
--------------------------------------------------------------------------------
[2022-06-18 08:08:33,220] {taskinstance.py:1239} INFO - Starting attempt 1 of 1
[2022-06-18 08:08:33,221] {taskinstance.py:1240} INFO - 
--------------------------------------------------------------------------------
[2022-06-18 08:08:33,273] {taskinstance.py:1259} INFO - Executing <Task(PythonOperator): run_etl_task> on 2022-06-18 08:08:29.183648+00:00
[2022-06-18 08:08:33,284] {standard_task_runner.py:52} INFO - Started process 3056 to run task
[2022-06-18 08:08:33,295] {standard_task_runner.py:76} INFO - Running: ['***', 'tasks', 'run', 'simple_etl_dag', 'run_etl_task', 'manual__2022-06-18T08:08:29.183648+00:00', '--job-id', '4', '--raw', '--subdir', 'DAGS_FOLDER/simple_etl.py', '--cfg-path', '/tmp/tmp2bipunn1', '--error-file', '/tmp/tmp360_fty8']
[2022-06-18 08:08:33,300] {standard_task_runner.py:77} INFO - Job 4: Subtask run_etl_task
[2022-06-18 08:08:33,507] {logging_mixin.py:109} INFO - Running <TaskInstance: simple_etl_dag.run_etl_task manual__2022-06-18T08:08:29.183648+00:00 [running]> on host b7a0af5ee6a4
[2022-06-18 08:08:33,854] {taskinstance.py:1426} INFO - Exporting the following env vars:
AIRFLOW_CTX_DAG_OWNER=Airflow
AIRFLOW_CTX_DAG_ID=simple_etl_dag
AIRFLOW_CTX_TASK_ID=run_etl_task
AIRFLOW_CTX_EXECUTION_DATE=2022-06-18T08:08:29.183648+00:00
AIRFLOW_CTX_DAG_RUN_ID=manual__2022-06-18T08:08:29.183648+00:00
[2022-06-18 08:08:33,862] {logging_mixin.py:109} INFO - >>> Running 'etl' function. Logged at 2022-06-18 08:08:33.860901+00:00
[2022-06-18 08:08:33,866] {logging_mixin.py:109} INFO - >>> Running 'connect_db' function. Logged at 2022-06-18 08:08:33.865640+00:00
[2022-06-18 08:08:33,869] {logging_mixin.py:109} INFO - Connecting to DB
[2022-06-18 08:08:33,873] {taskinstance.py:1700} ERROR - Task failed with exception
Traceback (most recent call last):
  File "/home/airflow/.local/lib/python3.7/site-packages/airflow/models/taskinstance.py", line 1329, in _run_raw_task
    self._execute_task_with_callbacks(context)
  File "/home/airflow/.local/lib/python3.7/site-packages/airflow/models/taskinstance.py", line 1455, in _execute_task_with_callbacks
    result = self._execute_task(context, self.task)
  File "/home/airflow/.local/lib/python3.7/site-packages/airflow/models/taskinstance.py", line 1511, in _execute_task
    result = execute_callable(context=context)
  File "/home/airflow/.local/lib/python3.7/site-packages/airflow/operators/python.py", line 174, in execute
    return_value = self.execute_callable()
  File "/home/airflow/.local/lib/python3.7/site-packages/airflow/operators/python.py", line 185, in execute_callable
    return self.python_callable(*self.op_args, **self.op_kwargs)
  File "/opt/airflow/dags/simple_etl.py", line 30, in inner
    to_execute = func(*args, **kwargs)
  File "/opt/airflow/dags/simple_etl.py", line 92, in etl
    db_engine = connect_db()
  File "/opt/airflow/dags/simple_etl.py", line 30, in inner
    to_execute = func(*args, **kwargs)
  File "/opt/airflow/dags/simple_etl.py", line 43, in connect_db
    engine = create_engine(connection_uri, pool_pre_ping=True)
  File "/home/airflow/.local/lib/python3.7/site-packages/sqlalchemy/engine/__init__.py", line 525, in create_engine
    return strategy.create(*args, **kwargs)
  File "/home/airflow/.local/lib/python3.7/site-packages/sqlalchemy/engine/strategies.py", line 54, in create
    u = url.make_url(name_or_url)
  File "/home/airflow/.local/lib/python3.7/site-packages/sqlalchemy/engine/url.py", line 229, in make_url
    return _parse_rfc1738_args(name_or_url)
  File "/home/airflow/.local/lib/python3.7/site-packages/sqlalchemy/engine/url.py", line 288, in _parse_rfc1738_args
    return URL(name, **components)
  File "/home/airflow/.local/lib/python3.7/site-packages/sqlalchemy/engine/url.py", line 71, in __init__
    self.port = int(port)
ValueError: invalid literal for int() with base 10: '\n    postgres@database:5432'
[2022-06-18 08:08:33,981] {taskinstance.py:1277} INFO - Marking task as FAILED. dag_id=simple_etl_dag, task_id=run_etl_task, execution_date=20220618T080829, start_date=20220618T080833, end_date=20220618T080833
[2022-06-18 08:08:34,107] {standard_task_runner.py:92} ERROR - Failed to execute job 4 for task run_etl_task
Traceback (most recent call last):
  File "/home/airflow/.local/lib/python3.7/site-packages/airflow/task/task_runner/standard_task_runner.py", line 85, in _start_by_fork
    args.func(args, dag=self.dag)
  File "/home/airflow/.local/lib/python3.7/site-packages/airflow/cli/cli_parser.py", line 48, in command
    return func(*args, **kwargs)
  File "/home/airflow/.local/lib/python3.7/site-packages/airflow/utils/cli.py", line 92, in wrapper
    return f(*args, **kwargs)
  File "/home/airflow/.local/lib/python3.7/site-packages/airflow/cli/commands/task_command.py", line 298, in task_run
    _run_task_by_selected_method(args, dag, ti)
  File "/home/airflow/.local/lib/python3.7/site-packages/airflow/cli/commands/task_command.py", line 107, in _run_task_by_selected_method
    _run_raw_task(args, ti)
  File "/home/airflow/.local/lib/python3.7/site-packages/airflow/cli/commands/task_command.py", line 184, in _run_raw_task
    error_file=args.error_file,
  File "/home/airflow/.local/lib/python3.7/site-packages/airflow/utils/session.py", line 70, in wrapper
    return func(*args, session=session, **kwargs)
  File "/home/airflow/.local/lib/python3.7/site-packages/airflow/models/taskinstance.py", line 1329, in _run_raw_task
    self._execute_task_with_callbacks(context)
  File "/home/airflow/.local/lib/python3.7/site-packages/airflow/models/taskinstance.py", line 1455, in _execute_task_with_callbacks
    result = self._execute_task(context, self.task)
  File "/home/airflow/.local/lib/python3.7/site-packages/airflow/models/taskinstance.py", line 1511, in _execute_task
    result = execute_callable(context=context)
  File "/home/airflow/.local/lib/python3.7/site-packages/airflow/operators/python.py", line 174, in execute
    return_value = self.execute_callable()
  File "/home/airflow/.local/lib/python3.7/site-packages/airflow/operators/python.py", line 185, in execute_callable
    return self.python_callable(*self.op_args, **self.op_kwargs)
  File "/opt/airflow/dags/simple_etl.py", line 30, in inner
    to_execute = func(*args, **kwargs)
  File "/opt/airflow/dags/simple_etl.py", line 92, in etl
    db_engine = connect_db()
  File "/opt/airflow/dags/simple_etl.py", line 30, in inner
    to_execute = func(*args, **kwargs)
  File "/opt/airflow/dags/simple_etl.py", line 43, in connect_db
    engine = create_engine(connection_uri, pool_pre_ping=True)
  File "/home/airflow/.local/lib/python3.7/site-packages/sqlalchemy/engine/__init__.py", line 525, in create_engine
    return strategy.create(*args, **kwargs)
  File "/home/airflow/.local/lib/python3.7/site-packages/sqlalchemy/engine/strategies.py", line 54, in create
    u = url.make_url(name_or_url)
  File "/home/airflow/.local/lib/python3.7/site-packages/sqlalchemy/engine/url.py", line 229, in make_url
    return _parse_rfc1738_args(name_or_url)
  File "/home/airflow/.local/lib/python3.7/site-packages/sqlalchemy/engine/url.py", line 288, in _parse_rfc1738_args
    return URL(name, **components)
  File "/home/airflow/.local/lib/python3.7/site-packages/sqlalchemy/engine/url.py", line 71, in __init__
    self.port = int(port)
ValueError: invalid literal for int() with base 10: '\n    postgres@database:5432'
[2022-06-18 08:08:34,153] {local_task_job.py:154} INFO - Task exited with return code 1
[2022-06-18 08:08:34,403] {local_task_job.py:264} INFO - 0 downstream tasks scheduled from follow-on schedule check
